2024-01-04 09:50:08.187 WARNING (MainThread) [asyncio] Executing <Task pending name='setup component analytics' coro=<_async_setup_component() running at /home/vscode/.local/lib/python3.11/site-packages/homeassistant/setup.py:288> wait_for=<Task pending name='Storage load core.analytics' coro=<Store._async_load() running at /home/vscode/.local/lib/python3.11/site-packages/homeassistant/helpers/storage.py:133> cb=[set.remove(), Task.task_wakeup()] created at /home/vscode/.local/lib/python3.11/site-packages/homeassistant/core.py:558> cb=[set.remove(), Task.task_wakeup()] created at /home/vscode/.local/lib/python3.11/site-packages/homeassistant/core.py:558> took 0.713 seconds
2024-01-04 09:50:38.780 WARNING (MainThread) [asyncio] Executing <Task pending name='setup component dhcp' coro=<_async_setup_component() running at /home/vscode/.local/lib/python3.11/site-packages/homeassistant/setup.py:321> cb=[set.remove(), Task.task_wakeup()] created at /home/vscode/.local/lib/python3.11/site-packages/homeassistant/core.py:558> took 0.109 seconds
2024-01-04 09:51:27.167 WARNING (MainThread) [asyncio] Executing <Task pending name='setup component bluetooth' coro=<_async_setup_component() running at /home/vscode/.local/lib/python3.11/site-packages/homeassistant/setup.py:288> wait_for=<Task pending name='Storage load bluetooth.remote_scanners' coro=<Store._async_load() running at /home/vscode/.local/lib/python3.11/site-packages/homeassistant/helpers/storage.py:133> cb=[set.remove(), Task.task_wakeup()] created at /home/vscode/.local/lib/python3.11/site-packages/homeassistant/core.py:558> cb=[set.remove(), Task.task_wakeup()] created at /home/vscode/.local/lib/python3.11/site-packages/homeassistant/core.py:558> took 0.151 seconds
2024-01-04 09:51:55.391 ERROR (MainThread) [homeassistant.config_entries] Error occurred loading flow for integration google_translate: No module named 'mutagen'
2024-01-04 09:51:55.395 ERROR (MainThread) [aiohttp.server] Error handling request
Traceback (most recent call last):
  File "/home/vscode/.local/lib/python3.11/site-packages/homeassistant/config_entries.py", line 2037, in _load_integration
    integration.get_platform("config_flow")
  File "/home/vscode/.local/lib/python3.11/site-packages/homeassistant/loader.py", line 833, in get_platform
    cache[full_name] = self._import_platform(platform_name)
                       ^^^^^^^^^^^^^^^^^^^^^^^^^^^^^^^^^^^^
  File "/home/vscode/.local/lib/python3.11/site-packages/homeassistant/loader.py", line 850, in _import_platform
    return importlib.import_module(f"{self.pkg_path}.{platform_name}")
           ^^^^^^^^^^^^^^^^^^^^^^^^^^^^^^^^^^^^^^^^^^^^^^^^^^^^^^^^^^^
  File "/usr/local/lib/python3.11/importlib/__init__.py", line 126, in import_module
    return _bootstrap._gcd_import(name[level:], package, level)
           ^^^^^^^^^^^^^^^^^^^^^^^^^^^^^^^^^^^^^^^^^^^^^^^^^^^^
  File "<frozen importlib._bootstrap>", line 1204, in _gcd_import
  File "<frozen importlib._bootstrap>", line 1176, in _find_and_load
  File "<frozen importlib._bootstrap>", line 1147, in _find_and_load_unlocked
  File "<frozen importlib._bootstrap>", line 690, in _load_unlocked
  File "<frozen importlib._bootstrap_external>", line 940, in exec_module
  File "<frozen importlib._bootstrap>", line 241, in _call_with_frames_removed
  File "/home/vscode/.local/lib/python3.11/site-packages/homeassistant/components/google_translate/config_flow.py", line 9, in <module>
    from homeassistant.components.tts import CONF_LANG
  File "/home/vscode/.local/lib/python3.11/site-packages/homeassistant/components/tts/__init__.py", line 19, in <module>
    import mutagen
ModuleNotFoundError: No module named 'mutagen'

During handling of the above exception, another exception occurred:

Traceback (most recent call last):
  File "/home/vscode/.local/lib/python3.11/site-packages/aiohttp/web_protocol.py", line 433, in _handle_request
    resp = await request_handler(request)
           ^^^^^^^^^^^^^^^^^^^^^^^^^^^^^^
  File "/home/vscode/.local/lib/python3.11/site-packages/aiohttp/web_app.py", line 504, in _handle
    resp = await handler(request)
           ^^^^^^^^^^^^^^^^^^^^^^
  File "/home/vscode/.local/lib/python3.11/site-packages/aiohttp/web_middlewares.py", line 117, in impl
    return await handler(request)
           ^^^^^^^^^^^^^^^^^^^^^^
  File "/home/vscode/.local/lib/python3.11/site-packages/homeassistant/components/http/security_filter.py", line 85, in security_filter_middleware
    return await handler(request)
           ^^^^^^^^^^^^^^^^^^^^^^
  File "/home/vscode/.local/lib/python3.11/site-packages/homeassistant/components/http/forwarded.py", line 100, in forwarded_middleware
    return await handler(request)
           ^^^^^^^^^^^^^^^^^^^^^^
  File "/home/vscode/.local/lib/python3.11/site-packages/homeassistant/components/http/request_context.py", line 28, in request_context_middleware
    return await handler(request)
           ^^^^^^^^^^^^^^^^^^^^^^
  File "/home/vscode/.local/lib/python3.11/site-packages/homeassistant/components/http/ban.py", line 80, in ban_middleware
    return await handler(request)
           ^^^^^^^^^^^^^^^^^^^^^^
  File "/home/vscode/.local/lib/python3.11/site-packages/homeassistant/components/http/auth.py", line 236, in auth_middleware
    return await handler(request)
           ^^^^^^^^^^^^^^^^^^^^^^
  File "/home/vscode/.local/lib/python3.11/site-packages/homeassistant/components/http/view.py", line 148, in handle
    result = await handler(request, **request.match_info)
             ^^^^^^^^^^^^^^^^^^^^^^^^^^^^^^^^^^^^^^^^^^^^
  File "/home/vscode/.local/lib/python3.11/site-packages/homeassistant/components/onboarding/views.py", line 208, in post
    await asyncio.gather(
  File "/home/vscode/.local/lib/python3.11/site-packages/homeassistant/config_entries.py", line 847, in async_init
    flow, result = await task
                   ^^^^^^^^^^
  File "/home/vscode/.local/lib/python3.11/site-packages/homeassistant/config_entries.py", line 865, in _async_init
    flow = await self.async_create_flow(handler, context=context, data=data)
           ^^^^^^^^^^^^^^^^^^^^^^^^^^^^^^^^^^^^^^^^^^^^^^^^^^^^^^^^^^^^^^^^^
  File "/home/vscode/.local/lib/python3.11/site-packages/homeassistant/config_entries.py", line 967, in async_create_flow
    await _load_integration(self.hass, handler_key, self._hass_config)
  File "/home/vscode/.local/lib/python3.11/site-packages/homeassistant/config_entries.py", line 2044, in _load_integration
    raise data_entry_flow.UnknownHandler
homeassistant.data_entry_flow.UnknownHandler
2024-01-04 09:52:24.320 ERROR (MainThread) [homeassistant.loader] Unexpected exception importing component homeassistant.components.cloud
Traceback (most recent call last):
  File "/home/vscode/.local/lib/python3.11/site-packages/homeassistant/loader.py", line 813, in get_component
    ComponentProtocol, importlib.import_module(self.pkg_path)
                       ^^^^^^^^^^^^^^^^^^^^^^^^^^^^^^^^^^^^^^
  File "/usr/local/lib/python3.11/importlib/__init__.py", line 126, in import_module
    return _bootstrap._gcd_import(name[level:], package, level)
           ^^^^^^^^^^^^^^^^^^^^^^^^^^^^^^^^^^^^^^^^^^^^^^^^^^^^
  File "<frozen importlib._bootstrap>", line 1204, in _gcd_import
  File "<frozen importlib._bootstrap>", line 1176, in _find_and_load
  File "<frozen importlib._bootstrap>", line 1147, in _find_and_load_unlocked
  File "<frozen importlib._bootstrap>", line 690, in _load_unlocked
  File "<frozen importlib._bootstrap_external>", line 940, in exec_module
  File "<frozen importlib._bootstrap>", line 241, in _call_with_frames_removed
  File "/home/vscode/.local/lib/python3.11/site-packages/homeassistant/components/cloud/__init__.py", line 9, in <module>
    from hass_nabucasa import Cloud
  File "/home/vscode/.local/lib/python3.11/site-packages/hass_nabucasa/__init__.py", line 15, in <module>
    from .auth import CloudError, CognitoAuth
  File "/home/vscode/.local/lib/python3.11/site-packages/hass_nabucasa/auth.py", line 11, in <module>
    import boto3
  File "/home/vscode/.local/lib/python3.11/site-packages/boto3/__init__.py", line 17, in <module>
    from boto3.session import Session
  File "/home/vscode/.local/lib/python3.11/site-packages/boto3/session.py", line 17, in <module>
    import botocore.session
  File "/home/vscode/.local/lib/python3.11/site-packages/botocore/session.py", line 26, in <module>
    import botocore.client
  File "/home/vscode/.local/lib/python3.11/site-packages/botocore/client.py", line 15, in <module>
    from botocore import waiter, xform_name
  File "/home/vscode/.local/lib/python3.11/site-packages/botocore/waiter.py", line 18, in <module>
    from botocore.docs.docstring import WaiterDocstring
  File "/home/vscode/.local/lib/python3.11/site-packages/botocore/docs/__init__.py", line 15, in <module>
    from botocore.docs.service import ServiceDocumenter
  File "/home/vscode/.local/lib/python3.11/site-packages/botocore/docs/service.py", line 14, in <module>
    from botocore.docs.client import (
  File "/home/vscode/.local/lib/python3.11/site-packages/botocore/docs/client.py", line 18, in <module>
    from botocore.docs.example import ResponseExampleDocumenter
  File "/home/vscode/.local/lib/python3.11/site-packages/botocore/docs/example.py", line 13, in <module>
    from botocore.docs.shape import ShapeDocumenter
  File "/home/vscode/.local/lib/python3.11/site-packages/botocore/docs/shape.py", line 19, in <module>
    from botocore.utils import is_json_value_header
  File "/home/vscode/.local/lib/python3.11/site-packages/botocore/utils.py", line 39, in <module>
    import botocore.httpsession
  File "/home/vscode/.local/lib/python3.11/site-packages/botocore/httpsession.py", line 45, in <module>
    from urllib3.contrib.pyopenssl import (
  File "/home/vscode/.local/lib/python3.11/site-packages/urllib3/contrib/pyopenssl.py", line 97, in <module>
    util.PROTOCOL_TLS: OpenSSL.SSL.SSLv23_METHOD,
    ^^^^^^^^^^^^^^^^^
AttributeError: module 'urllib3.util' has no attribute 'PROTOCOL_TLS'
2024-01-04 09:52:24.328 ERROR (MainThread) [homeassistant.setup] Setup failed for cloud: Unable to import component: Exception importing homeassistant.components.cloud
Traceback (most recent call last):
  File "/home/vscode/.local/lib/python3.11/site-packages/homeassistant/loader.py", line 813, in get_component
    ComponentProtocol, importlib.import_module(self.pkg_path)
                       ^^^^^^^^^^^^^^^^^^^^^^^^^^^^^^^^^^^^^^
  File "/usr/local/lib/python3.11/importlib/__init__.py", line 126, in import_module
    return _bootstrap._gcd_import(name[level:], package, level)
           ^^^^^^^^^^^^^^^^^^^^^^^^^^^^^^^^^^^^^^^^^^^^^^^^^^^^
  File "<frozen importlib._bootstrap>", line 1204, in _gcd_import
  File "<frozen importlib._bootstrap>", line 1176, in _find_and_load
  File "<frozen importlib._bootstrap>", line 1147, in _find_and_load_unlocked
  File "<frozen importlib._bootstrap>", line 690, in _load_unlocked
  File "<frozen importlib._bootstrap_external>", line 940, in exec_module
  File "<frozen importlib._bootstrap>", line 241, in _call_with_frames_removed
  File "/home/vscode/.local/lib/python3.11/site-packages/homeassistant/components/cloud/__init__.py", line 9, in <module>
    from hass_nabucasa import Cloud
  File "/home/vscode/.local/lib/python3.11/site-packages/hass_nabucasa/__init__.py", line 15, in <module>
    from .auth import CloudError, CognitoAuth
  File "/home/vscode/.local/lib/python3.11/site-packages/hass_nabucasa/auth.py", line 11, in <module>
    import boto3
  File "/home/vscode/.local/lib/python3.11/site-packages/boto3/__init__.py", line 17, in <module>
    from boto3.session import Session
  File "/home/vscode/.local/lib/python3.11/site-packages/boto3/session.py", line 17, in <module>
    import botocore.session
  File "/home/vscode/.local/lib/python3.11/site-packages/botocore/session.py", line 26, in <module>
    import botocore.client
  File "/home/vscode/.local/lib/python3.11/site-packages/botocore/client.py", line 15, in <module>
    from botocore import waiter, xform_name
  File "/home/vscode/.local/lib/python3.11/site-packages/botocore/waiter.py", line 18, in <module>
    from botocore.docs.docstring import WaiterDocstring
  File "/home/vscode/.local/lib/python3.11/site-packages/botocore/docs/__init__.py", line 15, in <module>
    from botocore.docs.service import ServiceDocumenter
  File "/home/vscode/.local/lib/python3.11/site-packages/botocore/docs/service.py", line 14, in <module>
    from botocore.docs.client import (
  File "/home/vscode/.local/lib/python3.11/site-packages/botocore/docs/client.py", line 18, in <module>
    from botocore.docs.example import ResponseExampleDocumenter
  File "/home/vscode/.local/lib/python3.11/site-packages/botocore/docs/example.py", line 13, in <module>
    from botocore.docs.shape import ShapeDocumenter
  File "/home/vscode/.local/lib/python3.11/site-packages/botocore/docs/shape.py", line 19, in <module>
    from botocore.utils import is_json_value_header
  File "/home/vscode/.local/lib/python3.11/site-packages/botocore/utils.py", line 39, in <module>
    import botocore.httpsession
  File "/home/vscode/.local/lib/python3.11/site-packages/botocore/httpsession.py", line 45, in <module>
    from urllib3.contrib.pyopenssl import (
  File "/home/vscode/.local/lib/python3.11/site-packages/urllib3/contrib/pyopenssl.py", line 97, in <module>
    util.PROTOCOL_TLS: OpenSSL.SSL.SSLv23_METHOD,
    ^^^^^^^^^^^^^^^^^
AttributeError: module 'urllib3.util' has no attribute 'PROTOCOL_TLS'

The above exception was the direct cause of the following exception:

Traceback (most recent call last):
  File "/home/vscode/.local/lib/python3.11/site-packages/homeassistant/setup.py", line 215, in _async_setup_component
    component = integration.get_component()
                ^^^^^^^^^^^^^^^^^^^^^^^^^^^
  File "/home/vscode/.local/lib/python3.11/site-packages/homeassistant/loader.py", line 821, in get_component
    raise ImportError(f"Exception importing {self.pkg_path}") from err
ImportError: Exception importing homeassistant.components.cloud
2024-01-04 09:52:24.464 WARNING (MainThread) [asyncio] Executing <Task pending name='setup component stt' coro=<_async_setup_component() running at /home/vscode/.local/lib/python3.11/site-packages/homeassistant/setup.py:321> cb=[set.remove(), Task.task_wakeup()] created at /home/vscode/.local/lib/python3.11/site-packages/homeassistant/core.py:558> took 0.111 seconds
2024-01-04 09:52:24.738 WARNING (MainThread) [asyncio] Executing <Task pending name='setup component tts' coro=<_async_setup_component() running at /home/vscode/.local/lib/python3.11/site-packages/homeassistant/setup.py:288> wait_for=<Future pending cb=[_chain_future.<locals>._call_check_cancel() at /usr/local/lib/python3.11/asyncio/futures.py:387, <1 more>, Task.task_wakeup()] created at /usr/local/lib/python3.11/asyncio/base_events.py:427> cb=[set.remove(), Task.task_wakeup()] created at /home/vscode/.local/lib/python3.11/site-packages/homeassistant/core.py:558> took 0.125 seconds
2024-01-04 09:52:24.866 WARNING (MainThread) [homeassistant.bootstrap] Waiting on integrations to complete setup: zone, scene, hardware, tag, timer, schedule, input_button, input_boolean, tts, counter, input_text, input_datetime, sun, input_select, input_number
2024-01-04 09:52:37.411 WARNING (MainThread) [asyncio] Executing <Task pending name='setup component stream' coro=<_async_setup_component() running at /home/vscode/.local/lib/python3.11/site-packages/homeassistant/setup.py:321> cb=[set.remove(), <1 more>, Task.task_wakeup()] created at /home/vscode/.local/lib/python3.11/site-packages/homeassistant/core.py:558> took 0.369 seconds
2024-01-04 09:52:39.992 ERROR (MainThread) [homeassistant.loader] Unexpected exception importing component homeassistant.components.mobile_app
Traceback (most recent call last):
  File "/home/vscode/.local/lib/python3.11/site-packages/homeassistant/loader.py", line 813, in get_component
    ComponentProtocol, importlib.import_module(self.pkg_path)
                       ^^^^^^^^^^^^^^^^^^^^^^^^^^^^^^^^^^^^^^
  File "/usr/local/lib/python3.11/importlib/__init__.py", line 126, in import_module
    return _bootstrap._gcd_import(name[level:], package, level)
           ^^^^^^^^^^^^^^^^^^^^^^^^^^^^^^^^^^^^^^^^^^^^^^^^^^^^
  File "<frozen importlib._bootstrap>", line 1204, in _gcd_import
  File "<frozen importlib._bootstrap>", line 1176, in _find_and_load
  File "<frozen importlib._bootstrap>", line 1147, in _find_and_load_unlocked
  File "<frozen importlib._bootstrap>", line 690, in _load_unlocked
  File "<frozen importlib._bootstrap_external>", line 940, in exec_module
  File "<frozen importlib._bootstrap>", line 241, in _call_with_frames_removed
  File "/home/vscode/.local/lib/python3.11/site-packages/homeassistant/components/mobile_app/__init__.py", line 5, in <module>
    from homeassistant.components import cloud, notify as hass_notify
  File "/home/vscode/.local/lib/python3.11/site-packages/homeassistant/components/cloud/__init__.py", line 9, in <module>
    from hass_nabucasa import Cloud
  File "/home/vscode/.local/lib/python3.11/site-packages/hass_nabucasa/__init__.py", line 15, in <module>
    from .auth import CloudError, CognitoAuth
  File "/home/vscode/.local/lib/python3.11/site-packages/hass_nabucasa/auth.py", line 11, in <module>
    import boto3
  File "/home/vscode/.local/lib/python3.11/site-packages/boto3/__init__.py", line 17, in <module>
    from boto3.session import Session
  File "/home/vscode/.local/lib/python3.11/site-packages/boto3/session.py", line 17, in <module>
    import botocore.session
  File "/home/vscode/.local/lib/python3.11/site-packages/botocore/session.py", line 26, in <module>
    import botocore.client
  File "/home/vscode/.local/lib/python3.11/site-packages/botocore/client.py", line 15, in <module>
    from botocore import waiter, xform_name
  File "/home/vscode/.local/lib/python3.11/site-packages/botocore/waiter.py", line 18, in <module>
    from botocore.docs.docstring import WaiterDocstring
  File "/home/vscode/.local/lib/python3.11/site-packages/botocore/docs/__init__.py", line 15, in <module>
    from botocore.docs.service import ServiceDocumenter
  File "/home/vscode/.local/lib/python3.11/site-packages/botocore/docs/service.py", line 14, in <module>
    from botocore.docs.client import (
  File "/home/vscode/.local/lib/python3.11/site-packages/botocore/docs/client.py", line 18, in <module>
    from botocore.docs.example import ResponseExampleDocumenter
  File "/home/vscode/.local/lib/python3.11/site-packages/botocore/docs/example.py", line 13, in <module>
    from botocore.docs.shape import ShapeDocumenter
  File "/home/vscode/.local/lib/python3.11/site-packages/botocore/docs/shape.py", line 19, in <module>
    from botocore.utils import is_json_value_header
  File "/home/vscode/.local/lib/python3.11/site-packages/botocore/utils.py", line 39, in <module>
    import botocore.httpsession
  File "/home/vscode/.local/lib/python3.11/site-packages/botocore/httpsession.py", line 45, in <module>
    from urllib3.contrib.pyopenssl import (
  File "/home/vscode/.local/lib/python3.11/site-packages/urllib3/contrib/pyopenssl.py", line 97, in <module>
    util.PROTOCOL_TLS: OpenSSL.SSL.SSLv23_METHOD,
    ^^^^^^^^^^^^^^^^^
AttributeError: module 'urllib3.util' has no attribute 'PROTOCOL_TLS'
2024-01-04 09:52:39.997 ERROR (MainThread) [homeassistant.setup] Setup failed for mobile_app: Unable to import component: Exception importing homeassistant.components.mobile_app
Traceback (most recent call last):
  File "/home/vscode/.local/lib/python3.11/site-packages/homeassistant/loader.py", line 813, in get_component
    ComponentProtocol, importlib.import_module(self.pkg_path)
                       ^^^^^^^^^^^^^^^^^^^^^^^^^^^^^^^^^^^^^^
  File "/usr/local/lib/python3.11/importlib/__init__.py", line 126, in import_module
    return _bootstrap._gcd_import(name[level:], package, level)
           ^^^^^^^^^^^^^^^^^^^^^^^^^^^^^^^^^^^^^^^^^^^^^^^^^^^^
  File "<frozen importlib._bootstrap>", line 1204, in _gcd_import
  File "<frozen importlib._bootstrap>", line 1176, in _find_and_load
  File "<frozen importlib._bootstrap>", line 1147, in _find_and_load_unlocked
  File "<frozen importlib._bootstrap>", line 690, in _load_unlocked
  File "<frozen importlib._bootstrap_external>", line 940, in exec_module
  File "<frozen importlib._bootstrap>", line 241, in _call_with_frames_removed
  File "/home/vscode/.local/lib/python3.11/site-packages/homeassistant/components/mobile_app/__init__.py", line 5, in <module>
    from homeassistant.components import cloud, notify as hass_notify
  File "/home/vscode/.local/lib/python3.11/site-packages/homeassistant/components/cloud/__init__.py", line 9, in <module>
    from hass_nabucasa import Cloud
  File "/home/vscode/.local/lib/python3.11/site-packages/hass_nabucasa/__init__.py", line 15, in <module>
    from .auth import CloudError, CognitoAuth
  File "/home/vscode/.local/lib/python3.11/site-packages/hass_nabucasa/auth.py", line 11, in <module>
    import boto3
  File "/home/vscode/.local/lib/python3.11/site-packages/boto3/__init__.py", line 17, in <module>
    from boto3.session import Session
  File "/home/vscode/.local/lib/python3.11/site-packages/boto3/session.py", line 17, in <module>
    import botocore.session
  File "/home/vscode/.local/lib/python3.11/site-packages/botocore/session.py", line 26, in <module>
    import botocore.client
  File "/home/vscode/.local/lib/python3.11/site-packages/botocore/client.py", line 15, in <module>
    from botocore import waiter, xform_name
  File "/home/vscode/.local/lib/python3.11/site-packages/botocore/waiter.py", line 18, in <module>
    from botocore.docs.docstring import WaiterDocstring
  File "/home/vscode/.local/lib/python3.11/site-packages/botocore/docs/__init__.py", line 15, in <module>
    from botocore.docs.service import ServiceDocumenter
  File "/home/vscode/.local/lib/python3.11/site-packages/botocore/docs/service.py", line 14, in <module>
    from botocore.docs.client import (
  File "/home/vscode/.local/lib/python3.11/site-packages/botocore/docs/client.py", line 18, in <module>
    from botocore.docs.example import ResponseExampleDocumenter
  File "/home/vscode/.local/lib/python3.11/site-packages/botocore/docs/example.py", line 13, in <module>
    from botocore.docs.shape import ShapeDocumenter
  File "/home/vscode/.local/lib/python3.11/site-packages/botocore/docs/shape.py", line 19, in <module>
    from botocore.utils import is_json_value_header
  File "/home/vscode/.local/lib/python3.11/site-packages/botocore/utils.py", line 39, in <module>
    import botocore.httpsession
  File "/home/vscode/.local/lib/python3.11/site-packages/botocore/httpsession.py", line 45, in <module>
    from urllib3.contrib.pyopenssl import (
  File "/home/vscode/.local/lib/python3.11/site-packages/urllib3/contrib/pyopenssl.py", line 97, in <module>
    util.PROTOCOL_TLS: OpenSSL.SSL.SSLv23_METHOD,
    ^^^^^^^^^^^^^^^^^
AttributeError: module 'urllib3.util' has no attribute 'PROTOCOL_TLS'

The above exception was the direct cause of the following exception:

Traceback (most recent call last):
  File "/home/vscode/.local/lib/python3.11/site-packages/homeassistant/setup.py", line 215, in _async_setup_component
    component = integration.get_component()
                ^^^^^^^^^^^^^^^^^^^^^^^^^^^
  File "/home/vscode/.local/lib/python3.11/site-packages/homeassistant/loader.py", line 821, in get_component
    raise ImportError(f"Exception importing {self.pkg_path}") from err
ImportError: Exception importing homeassistant.components.mobile_app
2024-01-04 09:52:40.004 ERROR (MainThread) [homeassistant.setup] Unable to set up dependencies of default_config. Setup failed for dependencies: cloud, mobile_app
2024-01-04 09:52:40.005 ERROR (MainThread) [homeassistant.setup] Setup failed for default_config: (DependencyError(...), 'Could not setup dependencies: cloud, mobile_app')
2024-01-04 09:52:40.371 WARNING (MainThread) [asyncio] Executing <Task pending name='Task-1464' coro=<async_setup.<locals>.initial_refresh() running at /home/vscode/.local/lib/python3.11/site-packages/homeassistant/components/homeassistant_alerts/__init__.py:104> wait_for=<Future pending cb=[Task.task_wakeup()] created at /usr/local/lib/python3.11/asyncio/base_events.py:427> cb=[set.remove()] created at /home/vscode/.local/lib/python3.11/site-packages/homeassistant/core.py:522> took 0.124 seconds
